<?xml version="1.0"?>
<robot xmlns:xacro="http://www.ros.org/wiki/xacro" name="mobile">
 xmlns:contromobiler="http://playerstage.sourceforge.net/gazebo/xmlschema/#contromobiler"

<xacro:include filename="$(find mobile_description)/urdf/materials.xacro"/>
<xacro:include filename="$(find mobile_description)/urdf/mobile.gazebo"/>

<link name="base_footprint">
   <visual>
      <origin xyz="0 0 0" rpy="0 0 0" />
      <geometry>
        <box size="0.001 0.001 0.001" />
      </geometry>
    </visual>
  </link>

  <joint name="base_link_joint" type="fixed">
    <origin xyz="0.0 0 0" rpy="0 0 0" />
    <parent link="base_footprint"/>
    <child link="base_link" />
  </joint>

<link name="base_link">
          <visual>
              <origin xyz="0 0 0.1" rpy="0 0 1.57"/>
              <geometry>
              <box size="0.2 .3 .1"/>           
              </geometry>
              <material name="blue">
              <color rgba="0 0 1 1"/>              
              </material>
          </visual>    
      <collision>
        <origin xyz="0 0 0.1" rpy="0 0 1.57"/>
        <geometry>
         <box size="0.2 .3 .1"/>
          </geometry>
</collision>
<inertial>
   <mass
        value="5.52" />
      <inertia
        ixx="0.0458"
        ixy="0"
        ixz="0"
        iyy="0.0229"
        iyz="0"
        izz="0.0595" />
</inertial>
</link>

<link name="wheel_1">
          <visual>
              <origin xyz="0 0 0" rpy="0 0 0"/>
              <geometry>
              <cylinder length="0.04" radius="0.05"/>          
              </geometry>
              <material name="blue">
              <color rgba="0 0 1 1"/>              
              </material>
          </visual>    
      <collision>
        <origin xyz="0 0 0" rpy="0 0 0"/>
        <geometry>
         <cylinder length="0.04" radius="0.05"/>
          </geometry>
</collision>
<inertial>
   <mass
        value="0.2" />
      <inertia
        ixx="0.0002"
        ixy="0"
        ixz="0"
        iyy="0.00015"
        iyz="0"
        izz="0.0002" />
</inertial>
</link>

<joint name="base_to_wheel1" type="continuous">
<parent link="base_link"/>
<child link="wheel_1"/>
<origin xyz="0.125 0.125 0.045" rpy="0 1.57 1.57"/>
<axis xyz="0 0 1"/>
</joint>

<link name="wheel_2">
          <visual>
              <origin xyz="0 0 0" rpy="0 0 0"/>
              <geometry>
              <cylinder length="0.04" radius="0.05"/>          
              </geometry>
              <material name="blue">
              <color rgba="0 0 1 1"/>              
              </material>
          </visual>    
      <collision>
        <origin xyz="0 0 0" rpy="0 0 0"/>
        <geometry>
         <cylinder length="0.04" radius="0.05"/>
          </geometry>
</collision>
<inertial>
  <mass
        value="0.2" />
      <inertia
        ixx="0.0002"
        ixy="0"
        ixz="0"
        iyy="0.00015"
        iyz="0"
        izz="0.0002" />
</inertial>
</link>

<joint name="base_to_wheel2" type="continuous">
<parent link="base_link"/>
<child link="wheel_2"/>
<origin xyz="-0.125 0.125 0.06" rpy="0 1.57 1.57"/>
<axis xyz="0 0 1"/>
</joint>

<link name="wheel_3">
          <visual>
              <origin xyz="0 0 0" rpy="0 0 0"/>
              <geometry>
              <cylinder length="0.04" radius="0.05"/>          
              </geometry>
              <material name="blue">
              <color rgba="0 0 1 1"/>              
              </material>
          </visual>    
      <collision>
        <origin xyz="0 0 0" rpy="0 0 0"/>
        <geometry>
         <cylinder length="0.04" radius="0.05"/>
          </geometry>
</collision>
<inertial>
  <mass
        value="0.2" />
      <inertia
        ixx="0.0002"
        ixy="0"
        ixz="0"
        iyy="0.00015"
        iyz="0"
        izz="0.0002" />
</inertial>
</link>

<joint name="base_to_wheel3" type="continuous">
<parent link="base_link"/>
<child link="wheel_3"/>
<origin xyz="0.125 -0.125 0.06" rpy="0 1.57 1.57"/>
<axis xyz="0 0 1"/>
</joint>

<link name="wheel_4">
          <visual>
              <origin xyz="0 0 0" rpy="0 0 0"/>
              <geometry>
              <cylinder length="0.04" radius="0.05"/>          
              </geometry>
              <material name="blue">
              <color rgba="0 0 1 1"/>              
              </material>
          </visual>    
      <collision>
        <origin xyz="0 0 0" rpy="0 0 0"/>
        <geometry>
         <cylinder length="0.04" radius="0.05"/>
          </geometry>
</collision>
<inertial>
   <mass
        value="0.2" />
      <inertia
        ixx="0.0002"
        ixy="0"
        ixz="0"
        iyy="0.00015"
        iyz="0"
        izz="0.0002" />
</inertial>
</link>


<joint name="base_to_wheel4" type="continuous">
<parent link="base_link"/>
<child link="wheel_4"/>
<origin xyz="-0.125 -0.125 0.06" rpy="0 1.57 1.57"/>
<axis xyz="0 0 1"/>
</joint>

<link name="camera_link">
          <visual>
              <origin xyz="0 0 0" rpy="0 0 0"/>
              <geometry>
              <sphere radius="0.01"/>       
              </geometry>
              <material name="blue">
              <color rgba="0 0 1 1"/>              
              </material>
          </visual>    
      <collision>
        <origin xyz="0 0 0" rpy="0 0 0"/>
        <geometry>
         <sphere radius="0.01"/> 
          </geometry>
</collision>
<inertial>
   <mass
        value="0.01" />
      <inertia
        ixx="0.00301717973628494"
        ixy="-3.18755438710738E-17"
        ixz="-6.24500451351651E-17"
        iyy="0.0176625083227497"
        iyz="-0.000444787144430361"
        izz="0.015853003043962" />
</inertial>
</link>

<joint name="camera_joint" type="fixed">
   <origin xyz="0.14 0 0.16" rpy="0 0 0" />
   <parent link="base_link"/>
   <child link="camera_link" />
<axis xyz="1 0 0"/>
</joint>

 <joint name="hokuyo_joint" type="fixed">
    <axis xyz="0 1 0" />
    <origin xyz="0 0 0.21" rpy="0 0 0"/>
    <parent link="base_link"/>
    <child link="hokuyo_link"/>
  </joint>

  <!-- Hokuyo Laser -->
  <link name="hokuyo_link">
    <collision>
      <origin xyz="0 0 0" rpy="0 0 0"/>
      <geometry>
    <box size="0.1 0.1 0.1"/>
      </geometry>
    </collision>

    <visual>
      <origin xyz="0 0 0" rpy="0 0 0"/>
      <geometry>
        <mesh filename="package://mobile_description/meshes/hokuyo.dae"/>
      </geometry>
    </visual>

    <inertial>
      <mass value="1e-5" />
      <origin xyz="0 0 0" rpy="0 0 0"/>
      <inertia ixx="1e-6" ixy="0" ixz="0" iyy="1e-6" iyz="0" izz="1e-6" />
    </inertial>
  </link>

<link name="sonar_link">
          <visual>
              <origin xyz="0 0 0" rpy="0 0 0"/>
              <geometry>
              <sphere radius="0.01"/>       
              </geometry>
              <material name="blue">
              <color rgba="0 0 1 1"/>              
              </material>
          </visual>    
      <collision>
        <origin xyz="0 0 0" rpy="0 0 0"/>
        <geometry>
         <sphere radius="0.01"/> 
          </geometry>
</collision>
<inertial>
   <mass
        value="0.01" />
      <inertia
        ixx="0.00301717973628494"
        ixy="-3.18755438710738E-17"
        ixz="-6.24500451351651E-17"
        iyy="0.0176625083227497"
        iyz="-0.000444787144430361"
        izz="0.015853003043962" />
</inertial>
</link>

<joint name="sonar_joint" type="fixed">
   <origin xyz="0.14 0.02 0.16" rpy="0 0 0" />
   <parent link="base_link"/>
   <child link="sonar_link" />
<axis xyz="0 1 0"/>
</joint>


<transmission name="tran1">
    <type>transmission_interface/SimpleTransmission</type>
    <joint name="base_to_wheel1">
      <hardwareInterface>EffortJointInterface</hardwareInterface>
    </joint>
    <actuator name="motor1">
      <hardwareInterface>EffortJointInterface</hardwareInterface>
      <mechanicalReduction>1</mechanicalReduction>
    </actuator>
</transmission>

<transmission name="tran2">
    <type>transmission_interface/SimpleTransmission</type>
    <joint name="base_to_wheel2">
      <hardwareInterface>EffortJointInterface</hardwareInterface>
    </joint>
    <actuator name="motor2">
      <hardwareInterface>EffortJointInterface</hardwareInterface>
      <mechanicalReduction>1</mechanicalReduction>
    </actuator>
</transmission>

<transmission name="tran3">
    <type>transmission_interface/SimpleTransmission</type>
    <joint name="base_to_wheel3">
      <hardwareInterface>EffortJointInterface</hardwareInterface>
    </joint>
    <actuator name="motor3">
      <hardwareInterface>EffortJointInterface</hardwareInterface>
      <mechanicalReduction>1</mechanicalReduction>
    </actuator>
</transmission>

<transmission name="tran4">
    <type>transmission_interface/SimpleTransmission</type>
    <joint name="base_to_wheel4">
      <hardwareInterface>EffortJointInterface</hardwareInterface>
    </joint>
    <actuator name="motor4">
      <hardwareInterface>EffortJointInterface</hardwareInterface>
      <mechanicalReduction>1</mechanicalReduction>
    </actuator>
</transmission>



</robot>

